<?xml version="1.0" ?>
<!-- =================================================================================== -->
<!-- |    This document was autogenerated by xacro from robot.urdf.xacro               | -->
<!-- |    EDITING THIS FILE BY HAND IS NOT RECOMMENDED                                 | -->
<!-- =================================================================================== -->
<robot name="robot">
  <material name="white">
    <color rgba="1 1 1 1"/>
  </material>
  <material name="orange">
    <color rgba="1 0.3 0.1 1"/>
  </material>
  <material name="blue">
    <color rgba="0.2 0.2 1 1"/>
  </material>
  <material name="black">
    <color rgba="0 0 0 1"/>
  </material>
  <!-- BASE LINK -->
  <link name="base_link"/>
  <!-- CHASSIS LINK -->
  <joint name="chassis_joint" type="fixed">
    <parent link="base_link"/>
    <child link="chassis"/>
    <origin xyz="-0.1 0 0"/>
  </joint>
  <link name="chassis">
    <visual>
      <origin xyz="0.15 0 0.075"/>
      <geometry>
        <box size="0.3 0.3 0.15"/>
      </geometry>
      <material name="white"/>
    </visual>
    <collision>
      <origin xyz="0.15 0 0.075"/>
      <geometry>
        <box size="0.3 0.3 0.15"/>
      </geometry>
    </collision>
    <inertial>
      <origin rpy="0 0 0" xyz="0.15 0 0.075"/>
      <mass value="0.5"/>
      <inertia ixx="0.004687499999999999" ixy="0.0" ixz="0.0" iyy="0.004687499999999999" iyz="0.0" izz="0.0075"/>
    </inertial>
  </link>
  <gazebo reference="chassis">
    <material>Gazebo/White</material>
  </gazebo>
  <!-- LEFT WHEEL LINK -->
  <joint name="left_wheel_joint" type="continuous">
    <parent link="base_link"/>
    <child link="left_wheel"/>
    <origin rpy="-1.5707963267948966 0 0" xyz="0 0.175 0"/>
    <axis xyz="0 0 1"/>
  </joint>
  <link name="left_wheel">
    <visual>
      <geometry>
        <cylinder length="0.04" radius="0.05"/>
      </geometry>
      <material name="blue"/>
    </visual>
    <collision>
      <geometry>
        <cylinder length="0.04" radius="0.05"/>
      </geometry>
    </collision>
    <inertial>
      <origin rpy="0 0 0" xyz="0 0 0"/>
      <mass value="0.1"/>
      <inertia ixx="7.583333333333335e-05" ixy="0.0" ixz="0.0" iyy="7.583333333333335e-05" iyz="0.0" izz="0.00012500000000000003"/>
    </inertial>
  </link>
  <gazebo reference="left_wheel">
    <material>Gazebo/Blue</material>
  </gazebo>
  <!-- RIGHT WHEEL LINK -->
  <joint name="right_wheel_joint" type="continuous">
    <parent link="base_link"/>
    <child link="right_wheel"/>
    <origin rpy="1.5707963267948966 0 0" xyz="0 -0.175 0"/>
    <axis xyz="0 0 -1"/>
  </joint>
  <link name="right_wheel">
    <visual>
      <geometry>
        <cylinder length="0.04" radius="0.05"/>
      </geometry>
      <material name="blue"/>
    </visual>
    <collision>
      <geometry>
        <cylinder length="0.04" radius="0.05"/>
      </geometry>
    </collision>
    <inertial>
      <origin rpy="0 0 0" xyz="0 0 0"/>
      <mass value="0.1"/>
      <inertia ixx="7.583333333333335e-05" ixy="0.0" ixz="0.0" iyy="7.583333333333335e-05" iyz="0.0" izz="0.00012500000000000003"/>
    </inertial>
  </link>
  <gazebo reference="right_wheel">
    <material>Gazebo/Blue</material>
  </gazebo>
  <!-- CASTER WHEEL FRONT -->
  <joint name="caster_wheel_joint" type="fixed">
    <parent link="chassis"/>
    <child link="caster_wheel"/>
    <origin xyz="0.24 0 0"/>
  </joint>
  <link name="caster_wheel">
    <visual>
      <geometry>
        <sphere radius="0.05"/>
      </geometry>
      <material name="black"/>
    </visual>
    <collision>
      <geometry>
        <sphere radius="0.05"/>
      </geometry>
    </collision>
    <inertial>
      <origin rpy="0 0 0" xyz="0 0 0"/>
      <mass value="0.1"/>
      <inertia ixx="0.00010000000000000005" ixy="0.0" ixz="0.0" iyy="0.00010000000000000005" iyz="0.0" izz="0.00010000000000000005"/>
    </inertial>
  </link>
  <gazebo reference="caster_wheel">
    <material>Gazebo/Black</material>
    <mu1 value="0.001"/>
    <mu2 value="0.001"/>
  </gazebo>
  <!-- CASTER WHEEL BACK -->
  <joint name="back_caster_wheel_joint" type="fixed">
    <parent link="chassis"/>
    <child link="back_caster_wheel"/>
    <origin xyz="0.05 0 0"/>
  </joint>
  <link name="back_caster_wheel">
    <visual>
      <geometry>
        <sphere radius="0.05"/>
      </geometry>
      <material name="black"/>
    </visual>
    <collision>
      <geometry>
        <sphere radius="0.05"/>
      </geometry>
    </collision>
    <inertial>
      <origin rpy="0 0 0" xyz="0 0 0"/>
      <mass value="0.1"/>
      <inertia ixx="0.00010000000000000005" ixy="0.0" ixz="0.0" iyy="0.00010000000000000005" iyz="0.0" izz="0.00010000000000000005"/>
    </inertial>
  </link>
  <gazebo reference="back_caster_wheel">
    <material>Gazebo/Black</material>
    <mu1 value="0.001"/>
    <mu2 value="0.001"/>
  </gazebo>
  <!-- ARM BASE -->
  <joint name="arm_base_joint" type="continuous">
    <axis xyz="0 0 1"/>
    <parent link="base_link"/>
    <child link="arm_base"/>
    <origin rpy="0 0 0" xyz="0.0 0.0 0.18"/>
  </joint>
  <link name="arm_base">
    <inertial>
      <origin rpy="0 0 0" xyz="0 0 0"/>
      <mass value="1.6004"/>
      <inertia ixx="0.00552196561445819" ixy="7.9550614501301E-10" ixz="-1.34378458924839E-09" iyy="0.00352397447953875" iyz="-1.10071809773382E-08" izz="0.00553739792746489"/>
    </inertial>
    <visual>
      <origin rpy="0 0 0" xyz="0 0 0"/>
      <geometry>
        <mesh filename="file:///home/lollo/Desktop/projects/SmartRobotics_Project/controller/install/robot/share/robot/description/meshes/arm_base.stl"/>
      </geometry>
      <material name="">
        <color rgba="0.79216 0.81961 0.93333 1"/>
      </material>
    </visual>
    <collision>
      <origin rpy="0 0 0" xyz="0 0 0"/>
      <geometry>
        <mesh filename="file:///home/lollo/Desktop/projects/SmartRobotics_Project/controller/install/robot/share/robot/description/meshes/arm_base.stl"/>
      </geometry>
    </collision>
  </link>
  <!-- BICEP -->
  <!-- <joint name="shoulder_joint" type="continuous">
      <axis xyz="0 1 0"/>
      <parent link="arm_base"/>
      <child link="bicep"/>
      <origin rpy="0 0 1.5708" xyz="-0.05166 0.0 0.20271"/>
   </joint>
   <link name="bicep">
      <inertial>
         <origin xyz="0.12821 3.5589E-06 0.052492" rpy="0 0 0" />
         <mass value="1.1198" />
         <inertia
            ixx="0.0012474"
            ixy="-5.4004E-07"
            ixz="-0.0013148"
            iyy="0.0072923"
            iyz="-1.8586E-07"
            izz="0.0068178" />
      </inertial>
      <visual>
         <origin xyz="0 0 0" rpy="0 -1.5708 0" />
         <geometry>
            <mesh filename="file://$(find robot)/description/meshes/bicep.stl" />
         </geometry>
         <material name=""> 
            <color rgba="0.79216 0.81961 0.93333 1" />
         </material>
      </visual>
      <collision>
         <origin xyz="0 0 0" rpy="0 -1.5708 0" />
         <geometry>
            <mesh filename="file://$(find robot)/description/meshes/bicep.stl" />
         </geometry>
      </collision>
   </link> -->
  <!-- TOP WRIST -->
  <!-- <joint name="top_wrist_joint" type="continuous">
      <axis xyz="0 1 0"/>
      <parent link="elbow"/>
      <child link="top_wrist"/>
      <origin rpy="0 0 0" xyz="0.0 0 0.20994"/>
   </joint>
   <link name="top_wrist">
      <inertial>
         <origin xyz="-9.1053E-08 -0.069257 -1.86629999995759E-07" rpy="0 0 0" />
         <mass value="0.27721" />
         <inertia
            ixx="0.00104290750143942"
            ixy="4.37155302268076E-09"
            ixz="-2.45049603914627E-09"
            iyy="0.000380518373895034"
            iyz="-7.56009835172156E-09"
            izz="0.00106006525067445" />
      </inertial>
      <visual>
         <origin xyz="0 0 0.13522" rpy="3.14 0 1.5708" />
         <geometry>
            <mesh filename="file://$(find robot)/description/meshes/wrist.stl" />
         </geometry>
         <material name="">
            <color rgba="0.79216 0.81961 0.93333 1" />
         </material>
      </visual>
      <collision>
         <origin xyz="0 0 0.13522" rpy="3.14 0 1.5708" />
         <geometry>
            <mesh filename="file://$(find robot)/description/meshes/wrist.stl" />
         </geometry>
      </collision>
   </link> -->
  <!-- BOTTON WRIST -->
  <!-- <joint name="bottom_wrist_joint" type="continuous">
      <axis xyz="0 1 0"/>
      <parent link="bicep"/>
      <child link="bottom_wrist"/>
      <origin rpy="0 0 0" xyz="0.0 -0.05194 0.269"/>
   </joint>
   <link name="bottom_wrist">
      <inertial>
         <origin xyz="-9.1053E-08 -0.069257 -1.86629999995759E-07" rpy="0 0 0" />
         <mass value="0.27721" />
         <inertia
            ixx="0.00104290750143942"
            ixy="4.37155302268076E-09"
            ixz="-2.45049603914627E-09"
            iyy="0.000380518373895034"
            iyz="-7.56009835172156E-09"
            izz="0.00106006525067445" />
      </inertial>
      <visual>
         <origin xyz="0 0 0.13522" rpy="3.14 0 1.5708" />
         <geometry>
            <mesh filename="file://$(find robot)/description/meshes/wrist.stl" />
         </geometry>
         <material name="">
         <color rgba="0.79216 0.81961 0.93333 1" />
      </material>
    </visual>
      <collision>
         <origin xyz="0 0 0.13522" rpy="3.14 0 1.5708" />
         <geometry>
            <mesh filename="file://$(find robot)/description/meshes/wrist.stl" />
         </geometry>
      </collision>
   </link> -->
  <!-- ELBOW -->
  <!-- <joint name="elbow_joint" type="continuous">
      <axis xyz="0 0 1"/>
      <parent link="bottom_wrist"/>
      <child link="elbow"/>
      <origin rpy="0 0 0" xyz="0.0 0 0.13522"/>
   </joint>
  <link name="elbow">
      <inertial>
         <origin xyz="-0.11109 1.1476E-08 0.046469" rpy="0 0 0" />
         <mass value="0.84845" />
         <inertia
            ixx="0.00079656"
            ixy="-7.8011E-10"
            ixz="0.00053616"
            iyy="0.003576"
            iyz="4.6326E-10"
            izz="0.0033698" />
      </inertial>
      <visual>
         <origin xyz="0.0 0.05163 0.20994" rpy="0 -1.5708 0" />
         <geometry>
            <mesh filename="file://$(find robot)/description/meshes/elbow.stl" />
         </geometry>
         <material name="">
            <color rgba="0.79216 0.81961 0.93333 1" />
         </material>
      </visual>
      <collision>
         <origin xyz="0.0 0.05163 0.20994" rpy="0 -1.5708 0" />
         <geometry>
            <mesh filename="file://$(find robot)/description/meshes/elbow.stl" />
         </geometry>
      </collision>
  </link> -->
  <!-- TRANSMISSIONS -->
  <transmission name="arm_base_trans" type="SimpleTransmission">
    <type>transmission_interface/SimpleTransmission</type>
    <actuator name="arm_base_motor">
      <hardwareInterface>hardware_interface/PositionJointInterface</hardwareInterface>
      <mechanicalReduction>1</mechanicalReduction>
    </actuator>
    <joint name="arm_base_joint">
      <hardwareInterface>hardware_interface/PositionJointInterface</hardwareInterface>
    </joint>
  </transmission>
  <!-- <transmission name="shoulder_trans" type="SimpleTransmission">
      <type>transmission_interface/SimpleTransmission</type>
      <actuator name="shoulder_motor">
         <hardwareInterface>hardware_interface/PositionJointInterface</hardwareInterface>
         <mechanicalReduction>1</mechanicalReduction>
      </actuator>
      <joint name="shoulder_joint">
         <hardwareInterface>hardware_interface/PositionJointInterface</hardwareInterface>
      </joint>
   </transmission>

   <transmission name="bottom_wrist_trans" type="SimpleTransmission">
      <type>transmission_interface/SimpleTransmission</type>
      <actuator name="bottom_wrist_motor">
         <hardwareInterface>hardware_interface/PositionJointInterface</hardwareInterface>
         <mechanicalReduction>1</mechanicalReduction>
      </actuator>
      <joint name="bottom_wrist_joint">
         <hardwareInterface>hardware_interface/PositionJointInterface</hardwareInterface>
      </joint>
   </transmission>

   <transmission name="elbow_trans" type="SimpleTransmission">
      <type>transmission_interface/SimpleTransmission</type>
      <actuator name="elbow_motor">
         <hardwareInterface>hardware_interface/PositionJointInterface</hardwareInterface>
         <mechanicalReduction>1</mechanicalReduction>
      </actuator>
      <joint name="elbow_joint">
         <hardwareInterface>hardware_interface/PositionJointInterface</hardwareInterface>
      </joint>
   </transmission>

   <transmission name="top_wrist_trans" type="SimpleTransmission">
      <type>transmission_interface/SimpleTransmission</type>
      <actuator name="top_wrist_motor">
         <hardwareInterface>hardware_interface/PositionJointInterface</hardwareInterface>
         <mechanicalReduction>1</mechanicalReduction>
      </actuator>
      <joint name="top_wrist_joint">
         <hardwareInterface>hardware_interface/PositionJointInterface</hardwareInterface>
      </joint>
   </transmission> -->
  <gazebo>
    <plugin filename="libgazebo_ros_diff_drive.so" name="diff_drive">
      <!-- Wheel Information -->
      <left_joint>left_wheel_joint</left_joint>
      <right_joint>right_wheel_joint</right_joint>
      <wheel_separation>0.35</wheel_separation>
      <wheel_diameter>0.1</wheel_diameter>
      <!-- Limits -->
      <max_wheel_torque>200</max_wheel_torque>
      <max_wheel_acceleration>10.0</max_wheel_acceleration>
      <!-- Output -->
      <odometry_frame>odom</odometry_frame>
      <robot_base_frame>base_link</robot_base_frame>
      <publish_odom>true</publish_odom>
      <publish_odom_tf>true</publish_odom_tf>
      <publish_wheel_tf>true</publish_wheel_tf>
    </plugin>
  </gazebo>
  <ros2_control name="GazeboSystem" type="system">
    <hardware>
      <plugin>gazebo_ros2_control/GazeboSystem</plugin>
    </hardware>
    <joint name="arm_base_joint">
      <command_interface name="position">
        <param name="min">-1000</param>
        <param name="max">1000</param>
      </command_interface>
      <state_interface name="position"/>
      <state_interface name="velocity"/>
      <state_interface name="effort"/>
    </joint>
  </ros2_control>
  <!-- <gazebo>
        <plugin name="gazebo_ros_control" filename="libgazebo_ros_control.so">
            <robotNamespace>/robot</robotNamespace>
            <controlPeriod>0.001</controlPeriod>
            <legacyModeNS>false</legacyModeNS>
        </plugin>
    </gazebo> -->
  <gazebo>
    <plugin filename="libgazebo_ros2_control.so" name="gazebo_ros2_control">
      <!--<robot_param>robot_description</robot_param>
	    	<robot_namespace> box_bot</robot_namespace>
		<robot_param_node>robot_state_publisher</robot_param_node>-->
      <parameters>/home/lollo/Desktop/projects/SmartRobotics_Project/controller/install/controller_system/share/controller_system/config/robot.yaml</parameters>
    </plugin>
  </gazebo>
  <!-- <gazebo>
        <plugin name="gazebo_ros_joint_state_publisher"
            filename="libgazebo_ros_joint_state_publisher.so">
            <update_rate>20</update_rate>
            <joint_name>slider_joint</joint_name>
            <joint_name>arm_joint</joint_name>
        </plugin>
    </gazebo> -->
  <!-- <gazebo>
        <plugin name="joint_state_publisher" filename="libgazebo_ros_joint_state_publisher.so">
            <update_rate>20</update_rate>
            <joint_name>arm_base_joint</joint_name>
            <joint_name>shoulder_joint</joint_name>
            <joint_name>bottom_wrist_joint</joint_name>
            <joint_name>elbow_joint</joint_name>
            <joint_name>top_wrist_joint</joint_name>
        </plugin>
    </gazebo> -->
</robot>
